2024-12-15 17:25:22,062 - INFO - Pika version 1.3.2 connecting to ('::1', 5672, 0, 0)
2024-12-15 17:25:22,063 - ERROR - Socket failed to connect: <socket.socket fd=8, family=10, type=1, proto=6, laddr=('::1', 57754, 0, 0)>; error=111 (Connection refused)
2024-12-15 17:25:22,063 - ERROR - TCP Connection attempt failed: ConnectionRefusedError(111, 'Connection refused'); dest=(<AddressFamily.AF_INET6: 10>, <SocketKind.SOCK_STREAM: 1>, 6, '', ('::1', 5672, 0, 0))
2024-12-15 17:25:22,063 - ERROR - AMQPConnector - reporting failure: AMQPConnectorSocketConnectError: ConnectionRefusedError(111, 'Connection refused')
2024-12-15 17:25:22,063 - INFO - Pika version 1.3.2 connecting to ('127.0.0.1', 5672)
2024-12-15 17:25:22,064 - ERROR - Socket failed to connect: <socket.socket fd=8, family=2, type=1, proto=6, laddr=('127.0.0.1', 35766)>; error=111 (Connection refused)
2024-12-15 17:25:22,064 - ERROR - TCP Connection attempt failed: ConnectionRefusedError(111, 'Connection refused'); dest=(<AddressFamily.AF_INET: 2>, <SocketKind.SOCK_STREAM: 1>, 6, '', ('127.0.0.1', 5672))
2024-12-15 17:25:22,064 - ERROR - AMQPConnector - reporting failure: AMQPConnectorSocketConnectError: ConnectionRefusedError(111, 'Connection refused')
2024-12-15 17:25:22,064 - ERROR - AMQP connection workflow failed: AMQPConnectionWorkflowFailed: 2 exceptions in all; last exception - AMQPConnectorSocketConnectError: ConnectionRefusedError(111, 'Connection refused'); first exception - AMQPConnectorSocketConnectError: ConnectionRefusedError(111, 'Connection refused').
2024-12-15 17:25:22,064 - ERROR - AMQPConnectionWorkflow - reporting failure: AMQPConnectionWorkflowFailed: 2 exceptions in all; last exception - AMQPConnectorSocketConnectError: ConnectionRefusedError(111, 'Connection refused'); first exception - AMQPConnectorSocketConnectError: ConnectionRefusedError(111, 'Connection refused')
2024-12-15 17:25:22,064 - ERROR - Connection workflow failed: AMQPConnectionWorkflowFailed: 2 exceptions in all; last exception - AMQPConnectorSocketConnectError: ConnectionRefusedError(111, 'Connection refused'); first exception - AMQPConnectorSocketConnectError: ConnectionRefusedError(111, 'Connection refused')
2024-12-15 17:25:22,064 - ERROR - Error in _create_connection().
Traceback (most recent call last):
  File "/home/codespace/.python/current/lib/python3.12/site-packages/pika/adapters/blocking_connection.py", line 451, in _create_connection
    raise self._reap_last_connection_workflow_error(error)
pika.exceptions.AMQPConnectionError
2024-12-16 13:07:31,894 - INFO - Pika version 1.3.2 connecting to ('::1', 5672, 0, 0)
2024-12-16 13:07:31,894 - ERROR - Socket failed to connect: <socket.socket fd=8, family=10, type=1, proto=6, laddr=('::1', 57426, 0, 0)>; error=111 (Connection refused)
2024-12-16 13:07:31,894 - ERROR - TCP Connection attempt failed: ConnectionRefusedError(111, 'Connection refused'); dest=(<AddressFamily.AF_INET6: 10>, <SocketKind.SOCK_STREAM: 1>, 6, '', ('::1', 5672, 0, 0))
2024-12-16 13:07:31,894 - ERROR - AMQPConnector - reporting failure: AMQPConnectorSocketConnectError: ConnectionRefusedError(111, 'Connection refused')
2024-12-16 13:07:31,895 - INFO - Pika version 1.3.2 connecting to ('127.0.0.1', 5672)
2024-12-16 13:07:31,895 - ERROR - Socket failed to connect: <socket.socket fd=8, family=2, type=1, proto=6, laddr=('127.0.0.1', 36478)>; error=111 (Connection refused)
2024-12-16 13:07:31,895 - ERROR - TCP Connection attempt failed: ConnectionRefusedError(111, 'Connection refused'); dest=(<AddressFamily.AF_INET: 2>, <SocketKind.SOCK_STREAM: 1>, 6, '', ('127.0.0.1', 5672))
2024-12-16 13:07:31,895 - ERROR - AMQPConnector - reporting failure: AMQPConnectorSocketConnectError: ConnectionRefusedError(111, 'Connection refused')
2024-12-16 13:07:31,895 - ERROR - AMQP connection workflow failed: AMQPConnectionWorkflowFailed: 2 exceptions in all; last exception - AMQPConnectorSocketConnectError: ConnectionRefusedError(111, 'Connection refused'); first exception - AMQPConnectorSocketConnectError: ConnectionRefusedError(111, 'Connection refused').
2024-12-16 13:07:31,895 - ERROR - AMQPConnectionWorkflow - reporting failure: AMQPConnectionWorkflowFailed: 2 exceptions in all; last exception - AMQPConnectorSocketConnectError: ConnectionRefusedError(111, 'Connection refused'); first exception - AMQPConnectorSocketConnectError: ConnectionRefusedError(111, 'Connection refused')
2024-12-16 13:07:31,895 - ERROR - Connection workflow failed: AMQPConnectionWorkflowFailed: 2 exceptions in all; last exception - AMQPConnectorSocketConnectError: ConnectionRefusedError(111, 'Connection refused'); first exception - AMQPConnectorSocketConnectError: ConnectionRefusedError(111, 'Connection refused')
2024-12-16 13:07:31,895 - ERROR - Error in _create_connection().
Traceback (most recent call last):
  File "/home/codespace/.python/current/lib/python3.12/site-packages/pika/adapters/blocking_connection.py", line 451, in _create_connection
    raise self._reap_last_connection_workflow_error(error)
pika.exceptions.AMQPConnectionError
2024-12-17 18:22:04,455 - INFO - Pika version 1.3.2 connecting to ('::1', 5672, 0, 0)
2024-12-17 18:22:04,457 - ERROR - Socket failed to connect: <socket.socket fd=8, family=10, type=1, proto=6, laddr=('::1', 35952, 0, 0)>; error=111 (Connection refused)
2024-12-17 18:22:04,457 - ERROR - TCP Connection attempt failed: ConnectionRefusedError(111, 'Connection refused'); dest=(<AddressFamily.AF_INET6: 10>, <SocketKind.SOCK_STREAM: 1>, 6, '', ('::1', 5672, 0, 0))
2024-12-17 18:22:04,457 - ERROR - AMQPConnector - reporting failure: AMQPConnectorSocketConnectError: ConnectionRefusedError(111, 'Connection refused')
2024-12-17 18:22:04,457 - INFO - Pika version 1.3.2 connecting to ('127.0.0.1', 5672)
2024-12-17 18:22:04,457 - ERROR - Socket failed to connect: <socket.socket fd=8, family=2, type=1, proto=6, laddr=('127.0.0.1', 55252)>; error=111 (Connection refused)
2024-12-17 18:22:04,457 - ERROR - TCP Connection attempt failed: ConnectionRefusedError(111, 'Connection refused'); dest=(<AddressFamily.AF_INET: 2>, <SocketKind.SOCK_STREAM: 1>, 6, '', ('127.0.0.1', 5672))
2024-12-17 18:22:04,457 - ERROR - AMQPConnector - reporting failure: AMQPConnectorSocketConnectError: ConnectionRefusedError(111, 'Connection refused')
2024-12-17 18:22:04,458 - ERROR - AMQP connection workflow failed: AMQPConnectionWorkflowFailed: 2 exceptions in all; last exception - AMQPConnectorSocketConnectError: ConnectionRefusedError(111, 'Connection refused'); first exception - AMQPConnectorSocketConnectError: ConnectionRefusedError(111, 'Connection refused').
2024-12-17 18:22:04,458 - ERROR - AMQPConnectionWorkflow - reporting failure: AMQPConnectionWorkflowFailed: 2 exceptions in all; last exception - AMQPConnectorSocketConnectError: ConnectionRefusedError(111, 'Connection refused'); first exception - AMQPConnectorSocketConnectError: ConnectionRefusedError(111, 'Connection refused')
2024-12-17 18:22:04,458 - ERROR - Connection workflow failed: AMQPConnectionWorkflowFailed: 2 exceptions in all; last exception - AMQPConnectorSocketConnectError: ConnectionRefusedError(111, 'Connection refused'); first exception - AMQPConnectorSocketConnectError: ConnectionRefusedError(111, 'Connection refused')
2024-12-17 18:22:04,458 - ERROR - Error in _create_connection().
Traceback (most recent call last):
  File "/usr/local/python/3.12.1/lib/python3.12/site-packages/pika/adapters/blocking_connection.py", line 451, in _create_connection
    raise self._reap_last_connection_workflow_error(error)
pika.exceptions.AMQPConnectionError
